Workbook
Name descriptions: DishDescriptions!$A$1:$K$591
Name Groups: RecipeNotes!$A$2:$A$36
Name recipe_notes: DishNotes!$A$1:$N$573

Sheet DishNotes
A1: dish_name | B1: dish_pk | C1: mltext_pk | D1: Type | E1: New guide | F1: Group | G1: New proposal | H1: New proposal | I1: en | J1: da | K1: de | L1: lv | M1: et
A2: Pickling | B2: 141 | C2: 1741 | D2: =VLOOKUP(B2,[1]ManipulationPage!$A$3:$D$541,4,FALSE) -> 0 | I2: Your vegetables will already gain a sour flavor within 30 minutes, but they gain more flavor the longer you keep them. Consume within 2 weeks. | J2: Your vegetables will already gain a sour flavor within 30 minutes, but they gain more flavor the longer you keep them. Consume within 2 weeks. | K2: Your vegetables will already gain a sour flavor within 30 minutes, but they gain more flavor the longer you keep them. Consume within 2 weeks.
A3: Asian Marinade | B3: 1094 | C3: 9263 | D3: =VLOOKUP(B3,[1]ManipulationPage!$A$3:$D$541,4,FALSE) -> Asia | F3: Marinade | G3: =VLOOKUP($F3,RecipeNotes!$A$2:$E$62,3,FALSE) -> Shortcut recipe: Mix ingredients and stir around with a fork. | H3: =VLOOKUP($F3,RecipeNotes!$A$2:$E$62,5,FALSE) -> Shortcut opskrift: Bland ingredienser og rør rundt med en gaffel. | I3: The longer you let your ingredients marinate, the deeper their flavor will be. | J3: Jo længere du lader dine ingredienser marinere, jo dybere vil deres smag være. | K3: Je länger du deine Zutaten marinieren lässt, desto intensiver wird ihr Geschmack.
A4: Asian Marinade | B4: 101 | C4: 1479 | D4: =VLOOKUP(B4,[1]ManipulationPage!$A$3:$D$541,4,FALSE) -> Asia | F4: Marinade | G4: =VLOOKUP($F4,RecipeNotes!$A$2:$E$62,3,FALSE) -> Shortcut recipe: Mix ingredients and stir around with a fork. | H4: =VLOOKUP($F4,RecipeNotes!$A$2:$E$62,5,FALSE) -> Shortcut opskrift: Bland ingredienser og rør rundt med en gaffel. | I4: The longer you let your ingredients marinate, the deeper their flavor will be. | J4: Jo længere du lader dine ingredienser marinere, jo dybere vil deres smag være. | K4: Je länger du deine Zutaten marinieren lässt, desto intensiver wird ihr Geschmack.
A5: Asian Salad | B5: 988 | C5: 5420 | D5: =VLOOKUP(B5,[1]ManipulationPage!$A$3:$D$541,4,FALSE) -> Asia | E5: ! | F5: =RecipeNotes!A5 -> Salad | G5: =VLOOKUP($F5,RecipeNotes!$A$2:$E$62,3,FALSE) -> Shortcut recipe: Cut and mix all ingredients. Taste and balance with salt, sugar, sour, and umami. | H5: =VLOOKUP($F5,RecipeNotes!$A$2:$E$62,5,FALSE) -> Shortcut opskrift: Skær og bland alle ingredienser. Smag til med salt, sukker, syre og umami. | I5: =RecipeNotes!B2 -> Fry your onions and spices with a bit of oil. Add your condiments. Add veggies to the pan. Cook your other ingredients on the side. Once all your ingredients are cooked and ready to eat, mix them. Before toppings, taste and balance your dish by adding salt, sugar, sour, or umami ingredients for increased flavor. Too sour? Add salt and sugar. Too spicy? Add oil and sugar. Too Salty? Add bitter ingredients or fresh herbs. Add toppings and enjoy! | J5: A delicious dressing is just as important as the tasty vegetables! | K5: Ein leckeres Dressing ist genauso wichtig wie das leckere Gemüse! | L5: Garšīga mērce ir tikpat svarīga, kā garšīgi dārzeņi. | M5: Hõrk kaste on sama oluline kui maitsvad köögiviljad!
A6: Chow Mein | B6: 3 | C6: 977 | D6: =VLOOKUP(B6,[1]ManipulationPage!$A$3:$D$541,4,FALSE) -> Asia | E6: ! | F6: Stir-Fry | G6: =VLOOKUP($F6,RecipeNotes!$A$2:$E$62,3,FALSE) -> Shortcut recipe: Fry onions and spices on a pan. Add veggies. Taste and balance with salt, sugar, sour, and umami. | H6: =VLOOKUP($F6,RecipeNotes!$A$2:$E$62,5,FALSE) -> Shortcut opskrift: Steg løg og krydderier på panden. Tilføj grøntsager Smag til med salt, sukker, syre og umami. | I6: The trick to the perfect Chow Mein is to cook the noodles until they are al dente and then rinse them with cold water to stop the cooking process. | J6: Tricket bag en perfekt Chow Mein er at koge nudlerne al dente, og så vaske dem i koldt vand, så kogeprocessen stopper brat | K6: Der Trick hinter dem perfekten Chow Mein ist, die Nudeln al dente zu kochen und sie dann mit kaltem Wasser abzuschrecken, um den Kochvorgang abrupt zu beenden.
A7: Congee | B7: 361 | D7: =VLOOKUP(B7,[1]ManipulationPage!$A$3:$D$541,4,FALSE) -> Asia | E7: ! | F7: Congee | G7: =VLOOKUP($F7,RecipeNotes!$A$2:$E$62,3,FALSE) -> Shortcut recipe: Fry onions and spices on a pan. Add rice and boiling water with stock, let simmer. Taste and balance with salt, sugar, sour, and umami. | H7: =VLOOKUP($F7,RecipeNotes!$A$2:$E$62,5,FALSE) -> Shortcut opskrift: Steg løg og krydderier på panden. Tilføj ris og kogt vand med buillon og lad simre. Smag til med salt, sukker, syre og umami.
A8: Japanese Omelette | B8: 31 | C8: 1135 | D8: =VLOOKUP(B8,[1]ManipulationPage!$A$3:$D$541,4,FALSE) -> Asia | E8: ! | F8: Omelette | G8: =VLOOKUP($F8,RecipeNotes!$A$2:$E$62,3,FALSE) -> Shortcut recipe: Fry onions and spices on a pan. Whisk eggs well with salt, then add to pan. Omelette is done when egg isn't runny. | H8: =VLOOKUP($F8,RecipeNotes!$A$2:$E$62,5,FALSE) -> Shortcut opskrift: Steg løg og krydderier på panden. Bland æg grundigt med salt og andre smags-ingredienser. Tilføj så til panden. Omeletten er klar, når ægget ikke løber længere. | I8: If you can crack an egg, then you can make an omelette! | J8: Hvis du slår et æg ud kan du lave en omelet! | K8: Wenn du ein Ei aufschlagen kannst, dann kannst du auch ein Omelette machen!
A9: Japanese Pasta | B9: 930 | D9: =VLOOKUP(B9,[1]ManipulationPage!$A$3:$D$541,4,FALSE) -> Asia | E9: ! | F9: Pasta | G9: =VLOOKUP($F9,RecipeNotes!$A$2:$E$62,3,FALSE) -> Shortcut recipe: Fry onions and spices on a pan. Mix with cooked pasta, including a cup of the pasta water (for creamy consistency). | H9: =VLOOKUP($F9,RecipeNotes!$A$2:$E$62,5,FALSE) -> Shortcut opskrift: Steg løg og krydderier på panden. Ibland den kogte pasta med en kop pasta vand.
A10: Kimchi Sandwich | B10: 552 | D10: =VLOOKUP(B10,[1]ManipulationPage!$A$3:$D$541,4,FALSE) -> Asia | F10: Sandwich | G10: =VLOOKUP($F10,RecipeNotes!$A$2:$E$62,3,FALSE) -> Shortcut recipe: Prepare your ingredients seperately and add as layers on the bread. | H10: =VLOOKUP($F10,RecipeNotes!$A$2:$E$62,5,FALSE) -> Shortcut opskrift: Forbered dine ingredienser sperat og put på brøddet i lag.
A11: Korean Kimchi Stew | B11: 1012 | C11: 5856 | D11: =VLOOKUP(B11,[1]ManipulationPage!$A$3:$D$541,4,FALSE) -> Asia | F11: Stew | G11: =VLOOKUP($F11,RecipeNotes!$A$2:$E$62,3,FALSE) -> Shortcut recipe: Fry onions and spices on a pan. Add veggies. Add water with stock/broth. Taste and balance with salt, sugar, sour, and umami. | H11: =VLOOKUP($F11,RecipeNotes!$A$2:$E$62,5,FALSE) -> Shortcut opskrift: Steg løg og krydderier på panden. Tilføj grøntsager Til føj vand med buillon. Smag til med salt, sukker, syre og umami. | I11: Stews gain even more flavor when kept in the fridge overnight so don't worry if you can't finish it all. | J11: Gryderetten får mere smag, når den opbevares i køleskabet natten over, så bare rolig hvis du ikke kan færdiggøre det hele. | K11: Eintöpfe schmecken noch intensiver, wenn sie über Nacht im Kühlschrank aufbewahrt wurden. Also keine Sorge, wenn du nicht alles auf einmal essen kannst! | L11: Sautējumi ir garšīgāki, ja tos pa nakti atstāj ledusskapī, tāpēc nesatraucieties, ja neapēdat to vienā dienā. | M11: Hautised saavad maitset veelgi juurde, kui neid üleöö külmkapis hoida, seega ära muretse, kui sa ei jõua kõike korraga ära süüa.
A12: Korean Pasta | B12: 931 | D12: =VLOOKUP(B12,[1]ManipulationPage!$A$3:$D$541,4,FALSE) -> Asia | E12: ! | F12: Pasta | G12: =VLOOKUP($F12,RecipeNotes!$A$2:$E$62,3,FALSE) -> Shortcut recipe: Fry onions and spices on a pan. Mix with cooked pasta, including a cup of the pasta water (for creamy consistency). | H12: =VLOOKUP($F12,RecipeNotes!$A$2:$E$62,5,FALSE) -> Shortcut opskrift: Steg løg og krydderier på panden. Ibland den kogte pasta med en kop pasta vand.
A13: Korean Style Pizza | B13: 61 | C13: 1289 | D13: =VLOOKUP(B13,[1]ManipulationPage!$A$3:$D$541,4,FALSE) -> Asia | E13: ! | F13: Pizza | G13: =VLOOKUP($F13,RecipeNotes!$A$2:$E$62,3,FALSE) -> Shortcut recipe: Make your suco of fried onions, spices, and your choice of paste. Add to pizza with your choice of veggies. | H13: =VLOOKUP($F13,RecipeNotes!$A$2:$E$62,5,FALSE) -> Shortcut opskrift: Smør din pizza sauce i tyndt lag (lavet af løg, krydderier og din sauce stegt på en pande). Tilføj dine grøntsager på toppen. | I13: - | J13: - | K13: -
A14: Miso Soup | B14: 56 | C14: 1259 | D14: =VLOOKUP(B14,[1]ManipulationPage!$A$3:$D$541,4,FALSE) -> Asia | E14: ! | F14: =RecipeNotes!A10 -> Chunky soup | G14: =VLOOKUP($F14,RecipeNotes!$A$2:$E$62,3,FALSE) -> Shortcut recipe: Fry onions and spices on a pan. Add veggies. Add water with stock/broth. Taste and balance with salt, sugar, sour, and umami. | H14: =VLOOKUP($F14,RecipeNotes!$A$2:$E$62,5,FALSE) -> Shortcut opskrift: Steg løg og krydderier på panden. Tilføj grøntsager Til føj vand med buillon. Smag til med salt, sukker, syre og umami. | I14: Miso is responsible for the deep umami flavor of this soup, don't shy away from adding more. | J14: Miso er det, som giver den dybe umamismag til suppen, så ikke vær bange for at tilføje mere! | K14: Miso ist verantwortlich für das intensive Umami-Aroma dieser Suppe. Gib ruhig nach deinem Geschmack mehr dazu!
A15: Pad Thai | B15: 258 | C15: 2422 | D15: =VLOOKUP(B15,[1]ManipulationPage!$A$3:$D$541,4,FALSE) -> Asia | E15: ! | F15: =RecipeNotes!A2 -> Stir-Fry | G15: =VLOOKUP($F15,RecipeNotes!$A$2:$E$62,3,FALSE) -> Shortcut recipe: Fry onions and spices on a pan. Add veggies. Taste and balance with salt, sugar, sour, and umami. | H15: =VLOOKUP($F15,RecipeNotes!$A$2:$E$62,5,FALSE) -> Shortcut opskrift: Steg løg og krydderier på panden. Tilføj grøntsager Smag til med salt, sukker, syre og umami. | I15: Cook on high heat to make your dish ready quicker! | J15: Kog panden på højeste volumen, så bliver retten færdig hurtigere. | K15: Arbeite mit sehr hoher Temperatur, damit dein Gericht schneller fertig ist!
A16: Ramen | B16: 1059 | C16: 7733 | D16: =VLOOKUP(B16,[1]ManipulationPage!$A$3:$D$541,4,FALSE) -> Asia | E16: ! | F16: =F14 -> Chunky soup | G16: =VLOOKUP($F16,RecipeNotes!$A$2:$E$62,3,FALSE) -> Shortcut recipe: Fry onions and spices on a pan. Add veggies. Add water with stock/broth. Taste and balance with salt, sugar, sour, and umami. | H16: =VLOOKUP($F16,RecipeNotes!$A$2:$E$62,5,FALSE) -> Shortcut opskrift: Steg løg og krydderier på panden. Tilføj grøntsager Til føj vand med buillon. Smag til med salt, sukker, syre og umami.
A17: Sichuan Roasted Veggies | B17: 317 | C17: 2714 | D17: =VLOOKUP(B17,[1]ManipulationPage!$A$3:$D$541,4,FALSE) -> Asia | E17: ! | F17: =RecipeNotes!A12 -> Oven roast | G17: =VLOOKUP($F17,RecipeNotes!$A$2:$E$62,3,FALSE) -> Shortcut recipe: Roast veggies with onion, spices, salt, and oil in the oven. Taste and balance with salt, sugar, sour, and umami. | H17: =VLOOKUP($F17,RecipeNotes!$A$2:$E$62,5,FALSE) -> Shortcut opskrift: Læg grøntsagerne i ovnen med løg, krydderier, salt og olie. Smag til med salt, sukker, syre og umami. | I17: Roasting your veggies gives them a deeper aromatic profile. Enjoy :) | J17: Roasting your veggies gives them a deeper aromatic profile. Enjoy :) | K17: Roasting your veggies gives them a deeper aromatic profile. Enjoy :)
A18: Sichuan Stir-Fry | B18: 967 | C18: 5060 | D18: =VLOOKUP(B18,[1]ManipulationPage!$A$3:$D$541,4,FALSE) -> Asia | E18: ! | F18: Stir-Fry | G18: =VLOOKUP($F18,RecipeNotes!$A$2:$E$62,3,FALSE) -> Shortcut recipe: Fry onions and spices on a pan. Add veggies. Taste and balance with salt, sugar, sour, and umami. | H18: =VLOOKUP($F18,RecipeNotes!$A$2:$E$62,5,FALSE) -> Shortcut opskrift: Steg løg og krydderier på panden. Tilføj grøntsager Smag til med salt, sukker, syre og umami. | I18: Cook on high heat to make your dish ready quicker! | J18: Kog panden på højeste volumen, så bliver retten færdig hurtigere. | K18: Arbeite mit sehr hoher Temperatur, damit dein Gericht schneller fertig ist! | L18: Lai ēdiena pagatavošana būtu ātrāka, gatavojiet augstākā temperatūrā. | M18: Kuumuta kõrgel kuumusel, et sinu roog kiiremini valmiks!
A19: Tofu Stir-Fry | B19: 969 | C19: 5088 | D19: =VLOOKUP(B19,[1]ManipulationPage!$A$3:$D$541,4,FALSE) -> Asia | E19: ! | F19: Stir-Fry | G19: =VLOOKUP($F19,RecipeNotes!$A$2:$E$62,3,FALSE) -> Shortcut recipe: Fry onions and spices on a pan. Add veggies. Taste and balance with salt, sugar, sour, and umami. | H19: =VLOOKUP($F19,RecipeNotes!$A$2:$E$62,5,FALSE) -> Shortcut opskrift: Steg løg og krydderier på panden. Tilføj grøntsager Smag til med salt, sukker, syre og umami. | I19: Cook on high heat to make your dish ready quicker! | J19: Kog panden på højeste volumen, så bliver retten færdig hurtigere. | K19: Arbeite mit sehr hoher Temperatur, damit dein Gericht schneller fertig ist! | L19: Lai ēdiena pagatavošana būtu ātrāka, gatavojiet to uz lielākas uguns. | M19: Kuumuta kõrgel kuumusel, et sinu roog kiiremini valmiks!
A20: Banana Protein Bites | B20: 389 | C20: 2928 | D20: =VLOOKUP(B20,[1]ManipulationPage!$A$3:$D$541,4,FALSE) -> Baking | F20: Energy Balls | G20: =VLOOKUP($F20,RecipeNotes!$A$2:$E$62,3,FALSE) -> Shortcut recipe: Mash until reaches a cookie dough-like consistency. Add a little more wet or dry ingredients if needed to get the right texture. Form into balls and enjoy! | H20: =VLOOKUP($F20,RecipeNotes!$A$2:$E$62,5,FALSE) -> Shortcut opskrift: Ælt indtil konsistensen minder om kagedej. Form indtil kugler. | I20: Simply put all the ingredients into a food processor and you're ready to roll your own energy balls. | J20: Læg blot alle dine valgte ingredienserne i en madprocessor, og så er du klar til at rulle dine egne energikugler. | K20: Simply put all the ingredients into a food processor and you're ready to roll your own energy balls.
A21: Banana slices | B21: 777 | C21: 3726 | D21: =VLOOKUP(B21,[1]ManipulationPage!$A$3:$D$541,4,FALSE) -> Baking | G21: =VLOOKUP($F21,RecipeNotes!$A$2:$E$62,3,FALSE) -> #N/A | H21: =VLOOKUP($F21,RecipeNotes!$A$2:$E$62,5,FALSE) -> #N/A
A22: Beetroot Choco Cake | B22: 447 | C22: 3066 | D22: =VLOOKUP(B22,[1]ManipulationPage!$A$3:$D$541,4,FALSE) -> Baking | F22: Cake | G22: =VLOOKUP($F22,RecipeNotes!$A$2:$E$62,3,FALSE) -> Shortcut recipe: Fold the dry ingredients gently into the wet ingredients. Bake at 180°C until a toothpick inserted in the middle comes out clean (about 40 minutes). | H22: =VLOOKUP($F22,RecipeNotes!$A$2:$E$62,5,FALSE) -> Shortcut opskrift: Fold de tørre ingredienser ind i de våde. Bag i ovnen indtil en tandstik kan komme ud af dem uden dej sidder fast (ca 40 minutter). | I22: Vegetables can indeed be used in cake! | J22: Grøntsager kan sagtens bruges i kage! | K22: Vegetables can indeed be used in cake!
A23: Berry Almond Brownie | B23: 627 | C23: 3389 | D23: =VLOOKUP(B23,[1]ManipulationPage!$A$3:$D$541,4,FALSE) -> Baking | F23: Cake | G23: =VLOOKUP($F23,RecipeNotes!$A$2:$E$62,3,FALSE) -> Shortcut recipe: Fold the dry ingredients gently into the wet ingredients. Bake at 180°C until a toothpick inserted in the middle comes out clean (about 40 minutes). | H23: =VLOOKUP($F23,RecipeNotes!$A$2:$E$62,5,FALSE) -> Shortcut opskrift: Fold de tørre ingredienser ind i de våde. Bag i ovnen indtil en tandstik kan komme ud af dem uden dej sidder fast (ca 40 minutter).
A24: Berry Almond Brownies | B24: 628 | C24: 3391 | D24: =VLOOKUP(B24,[1]ManipulationPage!$A$3:$D$541,4,FALSE) -> Baking | F24: Cake | G24: =VLOOKUP($F24,RecipeNotes!$A$2:$E$62,3,FALSE) -> Shortcut recipe: Fold the dry ingredients gently into the wet ingredients. Bake at 180°C until a toothpick inserted in the middle comes out clean (about 40 minutes). | H24: =VLOOKUP($F24,RecipeNotes!$A$2:$E$62,5,FALSE) -> Shortcut opskrift: Fold de tørre ingredienser ind i de våde. Bag i ovnen indtil en tandstik kan komme ud af dem uden dej sidder fast (ca 40 minutter).
A25: Berry Muffins | B25: 467 | C25: 3100 | D25: =VLOOKUP(B25,[1]ManipulationPage!$A$3:$D$541,4,FALSE) -> Baking | F25: Sweet muffin | G25: =VLOOKUP($F25,RecipeNotes!$A$2:$E$62,3,FALSE) -> Shortcut recipe: Gently mix the wet ingredients into the dry. Bake in oven until a toothpick comes out clean when pricking them (about 30 minutes) | H25: =VLOOKUP($F25,RecipeNotes!$A$2:$E$62,5,FALSE) -> Shortcut opskrift: Ælt de våde ingredienser indi i de tørre nænsomt. Bag i ovnen indtil en tandstik kan komme ud af dem uden dej sidder fast.
A26: Black Bean Brownies | B26: 457 | C26: 3081 | D26: =VLOOKUP(B26,[1]ManipulationPage!$A$3:$D$541,4,FALSE) -> Baking | F26: Cake | G26: =VLOOKUP($F26,RecipeNotes!$A$2:$E$62,3,FALSE) -> Shortcut recipe: Fold the dry ingredients gently into the wet ingredients. Bake at 180°C until a toothpick inserted in the middle comes out clean (about 40 minutes). | H26: =VLOOKUP($F26,RecipeNotes!$A$2:$E$62,5,FALSE) -> Shortcut opskrift: Fold de tørre ingredienser ind i de våde. Bag i ovnen indtil en tandstik kan komme ud af dem uden dej sidder fast (ca 40 minutter). | I26: Black beans provide softness and body to these brownies - and don't worry, the chocolate taste hides the bean flavor. | J26: Sorte bønner giver brownien blødhed og struktur - og bare rolig, chokoladen skjuler bønensmag. | K26: Black beans provide softness and body to these brownies - and don't worry, the chocolate taste hides the bean flavor.
A27: Bread Buns | B27: 1149 | C27: 10081 | D27: =VLOOKUP(B27,[1]ManipulationPage!$A$3:$D$541,4,FALSE) -> Baking | F27: Bread | G27: =VLOOKUP($F27,RecipeNotes!$A$2:$E$62,3,FALSE) -> Shortcut recipe: knead in the wet ingredients into the dry until no flour pockets remain. Raise for 5 hours and bake for 1 hour (180 degrees). | H27: =VLOOKUP($F27,RecipeNotes!$A$2:$E$62,5,FALSE) -> Shortcut opskrift: Ælt de våde ingredienser indi ide tørre, indtil der ikke er mel-lommer. Hæv i mindst 5 timer, bag i ovnen i en time (180 grader).
A28: Bread Pudding Dessert | B28: 421 | C28: 3012 | D28: =VLOOKUP(B28,[1]ManipulationPage!$A$3:$D$541,4,FALSE) -> Baking | G28: =VLOOKUP($F28,RecipeNotes!$A$2:$E$62,3,FALSE) -> #N/A | H28: =VLOOKUP($F28,RecipeNotes!$A$2:$E$62,5,FALSE) -> #N/A | I28: Experiment with different bread types for various flavors.
A29: Breakfast Buns | B29: 481 | C29: 3126 | D29: =VLOOKUP(B29,[1]ManipulationPage!$A$3:$D$541,4,FALSE) -> Baking | F29: Bread | G29: =VLOOKUP($F29,RecipeNotes!$A$2:$E$62,3,FALSE) -> Shortcut recipe: knead in the wet ingredients into the dry until no flour pockets remain. Raise for 5 hours and bake for 1 hour (180 degrees). | H29: =VLOOKUP($F29,RecipeNotes!$A$2:$E$62,5,FALSE) -> Shortcut opskrift: Ælt de våde ingredienser indi ide tørre, indtil der ikke er mel-lommer. Hæv i mindst 5 timer, bag i ovnen i en time (180 grader).
A30: Buchteln | B30: 743 | C30: 3658 | D30: =VLOOKUP(B30,[1]ManipulationPage!$A$3:$D$541,4,FALSE) -> Baking | F30: Cake | G30: =VLOOKUP($F30,RecipeNotes!$A$2:$E$62,3,FALSE) -> Shortcut recipe: Fold the dry ingredients gently into the wet ingredients. Bake at 180°C until a toothpick inserted in the middle comes out clean (about 40 minutes). | H30: =VLOOKUP($F30,RecipeNotes!$A$2:$E$62,5,FALSE) -> Shortcut opskrift: Fold de tørre ingredienser ind i de våde. Bag i ovnen indtil en tandstik kan komme ud af dem uden dej sidder fast (ca 40 minutter).
A31: Bundt Cake | B31: 1153 | C31: 10097 | D31: =VLOOKUP(B31,[1]ManipulationPage!$A$3:$D$541,4,FALSE) -> Baking | F31: Cake | G31: =VLOOKUP($F31,RecipeNotes!$A$2:$E$62,3,FALSE) -> Shortcut recipe: Fold the dry ingredients gently into the wet ingredients. Bake at 180°C until a toothpick inserted in the middle comes out clean (about 40 minutes). | H31: =VLOOKUP($F31,RecipeNotes!$A$2:$E$62,5,FALSE) -> Shortcut opskrift: Fold de tørre ingredienser ind i de våde. Bag i ovnen indtil en tandstik kan komme ud af dem uden dej sidder fast (ca 40 minutter).
A32: Chia Pudding | B32: 667 | C32: 3487 | D32: =VLOOKUP(B32,[1]ManipulationPage!$A$3:$D$541,4,FALSE) -> Baking | G32: =VLOOKUP($F32,RecipeNotes!$A$2:$E$62,3,FALSE) -> #N/A | H32: =VLOOKUP($F32,RecipeNotes!$A$2:$E$62,5,FALSE) -> #N/A | I32: Chia seeds will thicken your porridge, so don't worry if it looks too runny at first. | J32: Chia frø samler vand og bliver tykkere... så bare rolig, hvis den virker for løbende i starten. | K32: Chia verdickt deinen Brei, mache dir also keine Sorgen, wenn er zu Beginn zu flüssig aussieht.
A33: Choco Berry Muffins | B33: 826 | C33: 3830 | D33: =VLOOKUP(B33,[1]ManipulationPage!$A$3:$D$541,4,FALSE) -> Baking | F33: Sweet muffin | G33: =VLOOKUP($F33,RecipeNotes!$A$2:$E$62,3,FALSE) -> Shortcut recipe: Gently mix the wet ingredients into the dry. Bake in oven until a toothpick comes out clean when pricking them (about 30 minutes) | H33: =VLOOKUP($F33,RecipeNotes!$A$2:$E$62,5,FALSE) -> Shortcut opskrift: Ælt de våde ingredienser indi i de tørre nænsomt. Bag i ovnen indtil en tandstik kan komme ud af dem uden dej sidder fast. | I33: Soft and tender muffins can be made to fit for almost any occasion! Breakfast, snack, dessert, dinner...you name it! | J33: Soft and tender muffins can be made to fit for almost any occasion! Breakfast, snack, dessert, dinner...you name it! | K33: Soft and tender muffins can be made to fit for almost any occasion! Breakfast, snack, dessert, dinner...you name it!
A34: Chocolate Brownie | B34: 600 | D34: =VLOOKUP(B34,[1]ManipulationPage!$A$3:$D$541,4,FALSE) -> Baking | F34: Cake | G34: =VLOOKUP($F34,RecipeNotes!$A$2:$E$62,3,FALSE) -> Shortcut recipe: Fold the dry ingredients gently into the wet ingredients. Bake at 180°C until a toothpick inserted in the middle comes out clean (about 40 minutes). | H34: =VLOOKUP($F34,RecipeNotes!$A$2:$E$62,5,FALSE) -> Shortcut opskrift: Fold de tørre ingredienser ind i de våde. Bag i ovnen indtil en tandstik kan komme ud af dem uden dej sidder fast (ca 40 minutter).
A35: Chocolate Chip Banana Bread | B35: 429 | C35: 3037 | D35: =VLOOKUP(B35,[1]ManipulationPage!$A$3:$D$541,4,FALSE) -> Baking | F35: Banana bread | G35: =VLOOKUP($F35,RecipeNotes!$A$2:$E$62,3,FALSE) -> Shortcut recipe: Beat in the wet ingredients into the dry until no flour pockets remain. Do not overmix. Bake for 60 minutes (180 degrees) | H35: =VLOOKUP($F35,RecipeNotes!$A$2:$E$62,5,FALSE) -> Shortcut opskrift: Slå de våde ingredienser indi de tørre indtil der ikke er flere 'mel-lommer' i dejen. Bag i ca 60 minutter (180 grader). | I35: Banana bread with a chocolate twist. | J35: Bananbrød med et chokoladetwist. | K35: Banana bread with a chocolate twist.
A36: Chocolate Mousse | B36: 687 | C36: 3534 | D36: =VLOOKUP(B36,[1]ManipulationPage!$A$3:$D$541,4,FALSE) -> Baking | G36: =VLOOKUP($F36,RecipeNotes!$A$2:$E$62,3,FALSE) -> #N/A | H36: =VLOOKUP($F36,RecipeNotes!$A$2:$E$62,5,FALSE) -> #N/A | I36: Enjoy a rich and creamy chocolate mousse, aired to perfection!
A37: Cinnamon Swirls | B37: 477 | C37: 3118 | D37: =VLOOKUP(B37,[1]ManipulationPage!$A$3:$D$541,4,FALSE) -> Baking | G37: =VLOOKUP($F37,RecipeNotes!$A$2:$E$62,3,FALSE) -> #N/A | H37: =VLOOKUP($F37,RecipeNotes!$A$2:$E$62,5,FALSE) -> #N/A | I37: These cinnamon buns will have your kitchen smelling like heaven! | J37: Disse kanelsnegle vil få dit køkken til at dufte himmelsk! | K37: These cinnamon buns will have your kitchen smelling like heaven!
A38: Classic bundt cake | B38: 676 | C38: 3511 | D38: =VLOOKUP(B38,[1]ManipulationPage!$A$3:$D$541,4,FALSE) -> Baking | F38: Cake | G38: =VLOOKUP($F38,RecipeNotes!$A$2:$E$62,3,FALSE) -> Shortcut recipe: Fold the dry ingredients gently into the wet ingredients. Bake at 180°C until a toothpick inserted in the middle comes out clean (about 40 minutes). | H38: =VLOOKUP($F38,RecipeNotes!$A$2:$E$62,5,FALSE) -> Shortcut opskrift: Fold de tørre ingredienser ind i de våde. Bag i ovnen indtil en tandstik kan komme ud af dem uden dej sidder fast (ca 40 minutter).
A39: Classic bundt cake | B39: 685 | C39: 3529 | D39: =VLOOKUP(B39,[1]ManipulationPage!$A$3:$D$541,4,FALSE) -> Baking | F39: Cake | G39: =VLOOKUP($F39,RecipeNotes!$A$2:$E$62,3,FALSE) -> Shortcut recipe: Fold the dry ingredients gently into the wet ingredients. Bake at 180°C until a toothpick inserted in the middle comes out clean (about 40 minutes). | H39: =VLOOKUP($F39,RecipeNotes!$A$2:$E$62,5,FALSE) -> Shortcut opskrift: Fold de tørre ingredienser ind i de våde. Bag i ovnen indtil en tandstik kan komme ud af dem uden dej sidder fast (ca 40 minutter).
A40: Classic Cheesecake | B40: 391 | C40: 2937 | D40: =VLOOKUP(B40,[1]ManipulationPage!$A$3:$D$541,4,FALSE) -> Baking | F40: Cheesecake | G40: =VLOOKUP($F40,RecipeNotes!$A$2:$E$62,3,FALSE) -> Shortcut recipe: Bake crust for 10 minutes, then add 'cheese' in the springform, and bake for another 45 minutes. Put in fridge overnight. | H40: =VLOOKUP($F40,RecipeNotes!$A$2:$E$62,5,FALSE) -> Shortcut opskrift: Bag dejen i 10 minutter, tilføj derefter ost i springformen og bag i yderligere 45 mintter. Put i køleren over natten. | I40: It's cheesecake time! | J40: Det er cheesecake tid! | K40: It's cheesecake time!
...

Sheet RecipeNotes
A1: Resulting notes
A2: Stir-Fry | B2: =CookingComponents!B2&" "&CookingComponents!B8&" "&CookingComponents!B16&" "&CookingComponents!B21&" "&CookingComponents!B25&" "&CookingComponents!B26&" "&CookingComponents!B28 -> Fry your onions and spices with a bit of oil. Add your condiments. Add veggies to the pan. Cook your other ingredients on the side. Once all your ingredients are cooked and ready to eat, mix them. Before toppings, taste and balance your dish by adding salt, sugar, sour, or umami ingredients for increased flavor. Too sour? Add salt and sugar. Too spicy? Add oil and sugar. Too Salty? Add bitter ingredients or fresh herbs. Add toppings and enjoy! | C2: =CookingComponents!C2&" "&CookingComponents!C8&" "&CookingComponents!C25 -> Shortcut recipe: Fry onions and spices on a pan. Add veggies. Taste and balance with salt, sugar, sour, and umami. | D2: =LEN(C2) -> 114 | E2: =CookingComponents!E2&" "&CookingComponents!E8&" "&CookingComponents!E25 -> Shortcut opskrift: Steg løg og krydderier på panden. Tilføj grøntsager Smag til med salt, sukker, syre og umami.
A3: With noodles/grains | B3: =CookingComponents!B2&" "&CookingComponents!B8&" "&CookingComponents!B22&" "&CookingComponents!B25&" "&CookingComponents!B26&" "&CookingComponents!B28 -> Fry your onions and spices with a bit of oil. Add your condiments. Add veggies to the pan. Mix all your ingredients with your boiled grains/noodles. Before toppings, taste and balance your dish by adding salt, sugar, sour, or umami ingredients for increased flavor. Too sour? Add salt and sugar. Too spicy? Add oil and sugar. Too Salty? Add bitter ingredients or fresh herbs. Add toppings and enjoy! | C3: =CookingComponents!C2&" "&CookingComponents!C8&" "&CookingComponents!C22 -> Shortcut recipe: Fry onions and spices on a pan. Add veggies. Mix with cooked grains/noodles. | D3: =LEN(C3) -> 93 | E3: =CookingComponents!E2&" "&CookingComponents!E8&" "&CookingComponents!E22 -> Shortcut opskrift: Steg løg og krydderier på panden. Tilføj grøntsager Bland med kogte nudler/bælgfrugter/korn.
A4: Pasta | B4: =CookingComponents!B2&" "&CookingComponents!B8&" "&CookingComponents!B23&" "&CookingComponents!B25&" "&CookingComponents!B26&" "&CookingComponents!B28 -> Fry your onions and spices with a bit of oil. Add your condiments. Add veggies to the pan. Add 1/2 cup of the pasta water to the frying pan for a creamier consistency. Mix all your ingredients with your boiled pasta. Before toppings, taste and balance your dish by adding salt, sugar, sour, or umami ingredients for increased flavor. Too sour? Add salt and sugar. Too spicy? Add oil and sugar. Too Salty? Add bitter ingredients or fresh herbs. Add toppings and enjoy! | C4: =CookingComponents!C2&" "&CookingComponents!C23 -> Shortcut recipe: Fry onions and spices on a pan. Mix with cooked pasta, including a cup of the pasta water (for creamy consistency). | D4: =LEN(C4) -> 132 | E4: =CookingComponents!E2&" "&CookingComponents!E23 -> Shortcut opskrift: Steg løg og krydderier på panden. Ibland den kogte pasta med en kop pasta vand.
A5: Salad | B5: =CookingComponents!B10&" "&CookingComponents!B17&" "&CookingComponents!B25&" "&CookingComponents!B26&" "&CookingComponents!B28 -> Wash, cut and mix your base ingredients. Mix in your dressing: Oil, sour ingredients, salt, and sugar. Before toppings, taste and balance your dish by adding salt, sugar, sour, or umami ingredients for increased flavor. Too sour? Add salt and sugar. Too spicy? Add oil and sugar. Too Salty? Add bitter ingredients or fresh herbs. Add toppings and enjoy! | C5: =CookingComponents!C10&" "&CookingComponents!C25&" "&CookingComponents!C26&" "&CookingComponents!C28 -> Shortcut recipe: Cut and mix all ingredients. Taste and balance with salt, sugar, sour, and umami. | D5: =LEN(C5) -> 100 | E5: =CookingComponents!E10&" "&CookingComponents!E25&" "&CookingComponents!E26&" "&CookingComponents!E28 -> Shortcut opskrift: Skær og bland alle ingredienser. Smag til med salt, sukker, syre og umami.
A6: Omelette | B6: =CookingComponents!B2&" "&CookingComponents!B8&" "&CookingComponents!B13&" "&CookingComponents!B14&" "&CookingComponents!B28 -> Fry your onions and spices with a bit of oil. Add your condiments. Add veggies to the pan. Crack the eggs into a bowl and whisk well with salt and pepper, before adding to the pan. Run a spatula through the middle of the omelette and tilt the pan to fill up with the runny egg. Omelette is done when there's no more runny egg. Add toppings and enjoy! | C6: =CookingComponents!C2&" "&CookingComponents!C13&" "&CookingComponents!C14 -> Shortcut recipe: Fry onions and spices on a pan. Whisk eggs well with salt, then add to pan. Omelette is done when egg isn't runny. | D6: =LEN(C6) -> 131 | E6: =CookingComponents!E2&" "&CookingComponents!E13&" "&CookingComponents!E14 -> Shortcut opskrift: Steg løg og krydderier på panden. Bland æg grundigt med salt og andre smags-ingredienser. Tilføj så til panden. Omeletten er klar, når ægget ikke løber længere.
A7: Pizza | C7: =CookingComponents!C35 -> Shortcut recipe: Make your suco of fried onions, spices, and your choice of paste. Add to pizza with your choice of veggies. | D7: =LEN(C7) -> 124 | E7: =CookingComponents!E35 -> Shortcut opskrift: Smør din pizza sauce i tyndt lag (lavet af løg, krydderier og din sauce stegt på en pande). Tilføj dine grøntsager på toppen.
A8: Risotto | B8: =CookingComponents!B2&" "&CookingComponents!B7&" "&CookingComponents!B16&" "&CookingComponents!B21&" "&CookingComponents!B25&" "&CookingComponents!B26&" "&CookingComponents!B28 -> Fry your onions and spices with a bit of oil. Add your condiments. Add risotto rice to the pan and then slowly add water or stock while stirring. Cook your other ingredients on the side. Once all your ingredients are cooked and ready to eat, mix them. Before toppings, taste and balance your dish by adding salt, sugar, sour, or umami ingredients for increased flavor. Too sour? Add salt and sugar. Too spicy? Add oil and sugar. Too Salty? Add bitter ingredients or fresh herbs. Add toppings and enjoy! | C8: =CookingComponents!C2&" "&CookingComponents!C7&" "&CookingComponents!C16&" "&CookingComponents!C21 -> Shortcut recipe: Fry onions and spices on a pan. Add rice with a little wine, then add stock and boiling water gradually. | D8: =LEN(C8) -> 123 | E8: =CookingComponents!E2&" "&CookingComponents!E7&" "&CookingComponents!E16&" "&CookingComponents!E21 -> Shortcut opskrift: Steg løg og krydderier på panden. Tilføj ris med en smule vin. Tilføj kogende vand med buillon gradvist.
A9: Creamy soup | B9: =CookingComponents!B2&" "&CookingComponents!B8&" "&CookingComponents!B18&" "&CookingComponents!B19&" "&CookingComponents!B25&" "&CookingComponents!B26&" "&CookingComponents!B28 -> Fry your onions and spices with a bit of oil. Add your condiments. Add veggies to the pan. Add water with stock/broth. Add a splash of oil, then blend into your desired consistency. Before toppings, taste and balance your dish by adding salt, sugar, sour, or umami ingredients for increased flavor. Too sour? Add salt and sugar. Too spicy? Add oil and sugar. Too Salty? Add bitter ingredients or fresh herbs. Add toppings and enjoy! | C9: =CookingComponents!C2&" "&CookingComponents!C8&" "&CookingComponents!C18&" "&CookingComponents!C19&" "&CookingComponents!C25 -> Shortcut recipe: Fry onions and spices on a pan. Add veggies. Add water with stock/broth. Blend the soup. Taste and balance with salt, sugar, sour, and umami. | D9: =LEN(C9) -> 158 | E9: =CookingComponents!E2&" "&CookingComponents!E8&" "&CookingComponents!E18&" "&CookingComponents!E19&" "&CookingComponents!E25 -> Shortcut opskrift: Steg løg og krydderier på panden. Tilføj grøntsager Til føj vand med buillon. Blend suppen. Smag til med salt, sukker, syre og umami.
A10: Chunky soup | B10: =CookingComponents!B2&" "&CookingComponents!B8&" "&CookingComponents!B18&" "&CookingComponents!B25&" "&CookingComponents!B26&" "&CookingComponents!B28 -> Fry your onions and spices with a bit of oil. Add your condiments. Add veggies to the pan. Add water with stock/broth. Before toppings, taste and balance your dish by adding salt, sugar, sour, or umami ingredients for increased flavor. Too sour? Add salt and sugar. Too spicy? Add oil and sugar. Too Salty? Add bitter ingredients or fresh herbs. Add toppings and enjoy! | C10: =CookingComponents!C2&" "&CookingComponents!C8&" "&CookingComponents!C18&" "&CookingComponents!C25&" "&CookingComponents!C26&" "&CookingComponents!C28 -> Shortcut recipe: Fry onions and spices on a pan. Add veggies. Add water with stock/broth. Taste and balance with salt, sugar, sour, and umami. | D10: =LEN(C10) -> 144 | E10: =CookingComponents!E2&" "&CookingComponents!E8&" "&CookingComponents!E18&" "&CookingComponents!E25&" "&CookingComponents!E26&" "&CookingComponents!E28 -> Shortcut opskrift: Steg løg og krydderier på panden. Tilføj grøntsager Til føj vand med buillon. Smag til med salt, sukker, syre og umami.
A11: Stew | B11: =CookingComponents!B2&" "&CookingComponents!B8&" "&CookingComponents!B18&" "&CookingComponents!B25&" "&CookingComponents!B26&" "&CookingComponents!B28 -> Fry your onions and spices with a bit of oil. Add your condiments. Add veggies to the pan. Add water with stock/broth. Before toppings, taste and balance your dish by adding salt, sugar, sour, or umami ingredients for increased flavor. Too sour? Add salt and sugar. Too spicy? Add oil and sugar. Too Salty? Add bitter ingredients or fresh herbs. Add toppings and enjoy! | C11: =CookingComponents!C2&" "&CookingComponents!C8&" "&CookingComponents!C18&" "&CookingComponents!C25&" "&CookingComponents!C26&" "&CookingComponents!C28 -> Shortcut recipe: Fry onions and spices on a pan. Add veggies. Add water with stock/broth. Taste and balance with salt, sugar, sour, and umami. | D11: =LEN(C11) -> 144 | E11: =CookingComponents!E2&" "&CookingComponents!E8&" "&CookingComponents!E18&" "&CookingComponents!E25&" "&CookingComponents!E26&" "&CookingComponents!E28 -> Shortcut opskrift: Steg løg og krydderier på panden. Tilføj grøntsager Til føj vand med buillon. Smag til med salt, sukker, syre og umami.
A12: Oven roast | B12: =CookingComponents!B9&" "&CookingComponents!B21&" "&CookingComponents!B25&" "&CookingComponents!B26&" "&CookingComponents!B28 -> Mix your veggies with onions, spices, salt, and oil. Roast at 180 degrees until desired color and texture. Once all your ingredients are cooked and ready to eat, mix them. Before toppings, taste and balance your dish by adding salt, sugar, sour, or umami ingredients for increased flavor. Too sour? Add salt and sugar. Too spicy? Add oil and sugar. Too Salty? Add bitter ingredients or fresh herbs. Add toppings and enjoy! | C12: =CookingComponents!C9&" "&CookingComponents!C21&" "&CookingComponents!C25&" "&CookingComponents!C26&" "&CookingComponents!C28 -> Shortcut recipe: Roast veggies with onion, spices, salt, and oil in the oven. Taste and balance with salt, sugar, sour, and umami. | D12: =LEN(C12) -> 133 | E12: =CookingComponents!E9&" "&CookingComponents!E21&" "&CookingComponents!E25&" "&CookingComponents!E26&" "&CookingComponents!E28 -> Shortcut opskrift: Læg grøntsagerne i ovnen med løg, krydderier, salt og olie. Smag til med salt, sukker, syre og umami.
A13: Daal | B13: =CookingComponents!B2&" "&CookingComponents!B11&" "&CookingComponents!B25&" "&CookingComponents!B26&" "&CookingComponents!B28 -> Fry your onions and spices with a bit of oil. Add your condiments. Add lentils to the pan, and then slowly add water or stock while stirring. Before toppings, taste and balance your dish by adding salt, sugar, sour, or umami ingredients for increased flavor. Too sour? Add salt and sugar. Too spicy? Add oil and sugar. Too Salty? Add bitter ingredients or fresh herbs. Add toppings and enjoy! | C13: =CookingComponents!C2&" "&CookingComponents!C11&" "&CookingComponents!C25&" "&CookingComponents!C26&" "&CookingComponents!C28 -> Shortcut recipe: Fry onions and spices on a pan. Add lentils, then water with stock. Taste and balance with salt, sugar, sour, and umami. | D13: =LEN(C13) -> 139 | E13: =CookingComponents!E2&" "&CookingComponents!E11&" "&CookingComponents!E25&" "&CookingComponents!E26&" "&CookingComponents!E28 -> Shortcut opskrift: Steg løg og krydderier på panden. Tilføj linser, dernæst vand med buillon. Smag til med salt, sukker, syre og umami.
A14: Panzanella | B14: =CookingComponents!B2&" "&CookingComponents!B8&" "&CookingComponents!B12&" "&CookingComponents!B21&" "&CookingComponents!B25&" "&CookingComponents!B26&" "&CookingComponents!B28 -> Fry your onions and spices with a bit of oil. Add your condiments. Add veggies to the pan. Cut your bread in small cubes, mix with oil, salt and pepper and bake in the oven for 10-15 minutes. Once all your ingredients are cooked and ready to eat, mix them. Before toppings, taste and balance your dish by adding salt, sugar, sour, or umami ingredients for increased flavor. Too sour? Add salt and sugar. Too spicy? Add oil and sugar. Too Salty? Add bitter ingredients or fresh herbs. Add toppings and enjoy! | C14: =CookingComponents!C12 -> Shortcut recipe: 50% is bread. Cut bread in cubes, drizzle with oil and salt, and then bake in oven. Cook and add your other ingredients | D14: =LEN(C14) -> 136 | E14: =CookingComponents!E12 -> Shortcut opskrift: 50% er brød. Skær brøddet i kvadrater, tilføj olie og salt og bag i ovnen. Tilføj til de andre ingredienser.
A15: Tagine | B15: =B11 -> Fry your onions and spices with a bit of oil. Add your condiments. Add veggies to the pan. Add water with stock/broth. Before toppings, taste and balance your dish by adding salt, sugar, sour, or umami ingredients for increased flavor. Too sour? Add salt and sugar. Too spicy? Add oil and sugar. Too Salty? Add bitter ingredients or fresh herbs. Add toppings and enjoy! | C15: =CookingComponents!C2&" "&CookingComponents!C8&" "&CookingComponents!C25 -> Shortcut recipe: Fry onions and spices on a pan. Add veggies. Taste and balance with salt, sugar, sour, and umami. | D15: =LEN(C15) -> 114 | E15: =CookingComponents!E2&" "&CookingComponents!E8&" "&CookingComponents!E25 -> Shortcut opskrift: Steg løg og krydderier på panden. Tilføj grøntsager Smag til med salt, sukker, syre og umami.
A16: Borscht | B16: =B9 -> Fry your onions and spices with a bit of oil. Add your condiments. Add veggies to the pan. Add water with stock/broth. Add a splash of oil, then blend into your desired consistency. Before toppings, taste and balance your dish by adding salt, sugar, sour, or umami ingredients for increased flavor. Too sour? Add salt and sugar. Too spicy? Add oil and sugar. Too Salty? Add bitter ingredients or fresh herbs. Add toppings and enjoy! | C16: =CookingComponents!C2&" "&CookingComponents!C33&" "&CookingComponents!C18&" "&CookingComponents!C19&" "&CookingComponents!C25 -> Shortcut recipe: Fry onions and spices on a pan. Add the beets Add water with stock/broth. Blend the soup. Taste and balance with salt, sugar, sour, and umami. | D16: =LEN(C16) -> 159 | E16: =CookingComponents!E2&" "&CookingComponents!E33&" "&CookingComponents!E18&" "&CookingComponents!E19&" "&CookingComponents!E25 -> Shortcut opskrift: Steg løg og krydderier på panden. Tilføj rødbederne. Til føj vand med buillon. Blend suppen. Smag til med salt, sukker, syre og umami.
A17: Fried rice | B17: =CookingComponents!B6&" "&CookingComponents!B2&" "&CookingComponents!B8&" "&CookingComponents!B22&" "&CookingComponents!B25&" "&CookingComponents!B26&" "&CookingComponents!B28 -> Boil your rice and let them cool. Fry your onions and spices with a bit of oil. Add your condiments. Add veggies to the pan. Mix all your ingredients with your boiled grains/noodles. Before toppings, taste and balance your dish by adding salt, sugar, sour, or umami ingredients for increased flavor. Too sour? Add salt and sugar. Too spicy? Add oil and sugar. Too Salty? Add bitter ingredients or fresh herbs. Add toppings and enjoy! | C17: =CookingComponents!C2&" "&CookingComponents!C35&" "&CookingComponents!C34 -> Shortcut recipe: Fry onions and spices on a pan. Shortcut recipe: Make your suco of fried onions, spices, and your choice of paste. Add to pizza with your choice of veggies. Add an umami sauce, sugar, and cold rice that was cooked the day before, and fry for a few more minutes. | D17: =LEN(C17) -> 278 | E17: =CookingComponents!E2&" "&CookingComponents!E35&" "&CookingComponents!E34 -> Shortcut opskrift: Steg løg og krydderier på panden. Shortcut opskrift: Smør din pizza sauce i tyndt lag (lavet af løg, krydderier og din sauce stegt på en pande). Tilføj dine grøntsager på toppen. Tilføj en umami sauce, sukker, og kold ris fra dagen før. Steg i et par minutter
A18: Tacos | C18: =CookingComponents!C2&" "&CookingComponents!C8&" "&CookingComponents!C25&" "&CookingComponents!C31 -> Shortcut recipe: Fry onions and spices on a pan. Add veggies. Taste and balance with salt, sugar, sour, and umami. Add all to the tacos. Enjoy! | D18: =LEN(C18) -> 143 | E18: =CookingComponents!E2&" "&CookingComponents!E8&" "&CookingComponents!E25&" "&CookingComponents!E31 -> Shortcut opskrift: Steg løg og krydderier på panden. Tilføj grøntsager Smag til med salt, sukker, syre og umami. Tilføj alt i dine tacos.
A19: Summer rolls | C19: =CookingComponents!C2&" "&CookingComponents!C8&" "&CookingComponents!C25&" "&CookingComponents!C32 -> Shortcut recipe: Fry onions and spices on a pan. Add veggies. Taste and balance with salt, sugar, sour, and umami. Soften rice paper in warm water, then fill with your ingredients. Enjoy! | D19: =LEN(C19) -> 187 | E19: =CookingComponents!E2&" "&CookingComponents!E8&" "&CookingComponents!E25&" "&CookingComponents!E32 -> Shortcut opskrift: Steg løg og krydderier på panden. Tilføj grøntsager Smag til med salt, sukker, syre og umami. Blødgør rispapiret i varmt vand, fyld så med dine ingredienser.
A20: Pilaf | C20: =CookingComponents!C2&" "&CookingComponents!C36 -> Shortcut recipe: Fry onions and spices on a pan. Add rice and toast them briefly. Then add water (with stock) to boil as usual. | D20: =LEN(C20) -> 127 | E20: =CookingComponents!E2&" "&CookingComponents!E36 -> Shortcut opskrift: Steg løg og krydderier på panden. Tilføj ris og rist dem kort. Tilføj vand med buillon og kog risene.
A21: Loaded potato | C21: =CookingComponents!C37 -> Shortcut recipe: Bake whole potato for up to an hour in oven, scoop out half the inside, and add your filling | D21: =LEN(C21) -> 109 | E21: =CookingComponents!E37 -> Shortcut opskrift: Bag den hele kartoffel i op til en time i ovnen. Grav halvdelen af indmaden ud og tilføj din filling.
A22: Polenta | C22: =CookingComponents!C38&" "&CookingComponents!C5&" "&CookingComponents!C25 -> Shortcut recipe: Whisk polenta into boiling water (with stock) bit-by-bit. Add your veggies and condiments. Taste and balance with salt, sugar, sour, and umami. | D22: =LEN(C22) -> 160 | E22: =CookingComponents!E38&" "&CookingComponents!E5&" "&CookingComponents!E25 -> Shortcut opskrift: Bag den hele kartoffel i op til en time i ovnen. Grav halvdelen af indmaden ud og tilføj din filling. Tilføj dine grøntsager og saucer. Smag til med salt, sukker, syre og umami.
A23: Wraps | C23: =CookingComponents!C2&" "&CookingComponents!C8&" "&CookingComponents!C25&" "&CookingComponents!C42&" "&CookingComponents!C43 -> Shortcut recipe: Fry onions and spices on a pan. Add veggies. Taste and balance with salt, sugar, sour, and umami. Pluck the leaves off your cabbage/lettuce, to be used as 'tacos'. Add all to the 'tacos'. Enjoy! | D23: =LEN(C23) -> 211 | E23: =CookingComponents!E2&" "&CookingComponents!E8&" "&CookingComponents!E25&" "&CookingComponents!E42&" "&CookingComponents!E43 -> Shortcut opskrift: Steg løg og krydderier på panden. Tilføj grøntsager Smag til med salt, sukker, syre og umami. Pluk bladene forsigtigt af dine kål/salat for at bruge dem som 'tacos'. Tilføj i din 'tacos'.
A24: Burrito | C24: =CookingComponents!C2&" "&CookingComponents!C8&" "&CookingComponents!C25&" "&CookingComponents!C44 -> Shortcut recipe: Fry onions and spices on a pan. Add veggies. Taste and balance with salt, sugar, sour, and umami. Add all in the burritos. Enjoy | D24: =LEN(C24) -> 145 | E24: =CookingComponents!E2&" "&CookingComponents!E8&" "&CookingComponents!E25&" "&CookingComponents!E44 -> Shortcut opskrift: Steg løg og krydderier på panden. Tilføj grøntsager Smag til med salt, sukker, syre og umami. Tilføj alt i dine burritos.
A25: Porridge | C25: =CookingComponents!C51 -> Shortcut recipe: Add boiling water to oats with a bit of salt. Wait 5 minutes. Then add your condiments | D25: =LEN(C25) -> 103 | E25: =CookingComponents!E51 -> Shortcut opskrift: Tilføj kogende vand og en smule salt - vent 5 minutter… vupti!
A26: Congee | C26: =CookingComponents!C2&" "&CookingComponents!C39&" "&CookingComponents!C25 -> Shortcut recipe: Fry onions and spices on a pan. Add rice and boiling water with stock, let simmer. Taste and balance with salt, sugar, sour, and umami. | D26: =LEN(C26) -> 152 | E26: =CookingComponents!E2&" "&CookingComponents!E39&" "&CookingComponents!E25 -> Shortcut opskrift: Steg løg og krydderier på panden. Tilføj ris og kogt vand med buillon og lad simre. Smag til med salt, sukker, syre og umami.
A27: Broccoli/cauliflower rice | C27: =CookingComponents!C40&" "&CookingComponents!C25 -> Shortcut recipe: Grate or use your food processor to make it into 'rice'. Add your spices and condiments. Taste and balance with salt, sugar, sour, and umami. | D27: =LEN(C27) -> 158 | E27: =CookingComponents!E40&" "&CookingComponents!E25 -> Shortcut opskrift: Riv eller brug food processeren til at lave 'ris' af din grøntsag. Tilføj dine andre ingredienser. Smag til med salt, sukker, syre og umami.
A28: Gazpacho | C28: =CookingComponents!C41&" "&CookingComponents!C25 -> Shortcut recipe: Add veggies with bread to a blender and pulse to the desired texture. Cool it down in fridge. Taste and balance with salt, sugar, sour, and umami. | D28: =LEN(C28) -> 163 | E28: =CookingComponents!E41&" "&CookingComponents!E25 -> Shortcut opskrift: Tilføj grøntsager med brød i blenderen og glend til din ønskede tekstur. Lad hvile i køleren i mindst en halv time. Smag til med salt, sukker, syre og umami.
A29: Mash | C29: =CookingComponents!C45 -> Shortcut recipe: Mash your veggie with a blender or fork, mixing in some oil or butter for creaminess. | D29: =LEN(C29) -> 102 | E29: =CookingComponents!E45 -> Shortcut opskrift: Blend dine grøntsager med lidt smør/olie med en gaffel eller en blender.
A30: Moussaka | C30: =CookingComponents!C46 -> Shortcut recipe: Alternate between layers of thin-sliced veggies and sauce. Bake in the oven for 30+ minutes (180 degrees). | D30: =LEN(C30) -> 123 | E30: =CookingComponents!E46 -> Shortcut opskrift: Skift mellem lag a tyndt skårne grøntsager og din sovs. Bag i ovnen i +30 minutter ved 180 grader.
A31: Lasagna | C31: =CookingComponents!C47 -> Shortcut recipe: Alternate between layers of pasta and sauce. Bake in the oven for 30+ minutes (180 degrees). | D31: =LEN(C31) -> 109 | E31: =CookingComponents!E47 -> Shortcut opskrift: Skift mellem lag a pasta og din sovs. Bag i ovnen i +30 minutter ved 180 grader.
A32: Casserole | C32: =CookingComponents!C48 -> Shortcut recipe: Put a layer of cooked grains on-top of your sauce. Bake in the oven for 30+ minutes (180 degrees) | D32: =LEN(C32) -> 114 | E32: =CookingComponents!E48 -> Shortcut opskrift: Put et lag af dine kogte korn på toppen. Bag i ovnen i +30 minutter ved 180 grader.
A33: Quiche | C33: =CookingComponents!C49 -> Shortcut recipe: Add your ingredients into a pie crust, then pour a whisked egg mixture on top. Bake for 30+ minutes (180 degrees). | D33: =LEN(C33) -> 131 | E33: =CookingComponents!E49 -> Shortcut opskrift: Tilføj dine ingredineser i din tærtedej. Hæld et rørt æg ind i blandingen. Bag i ovnen i +30 minutter ved 180 grader.
A34: Burger pattys | C34: =CookingComponents!C50 -> Shortcut recipe: Mash ingredients with a fork or a blender. Shape patties in your hands and fry them on a pan with oil (5 minutes on each side). | D34: =LEN(C34) -> 144 | E34: =CookingComponents!E50 -> Shortcut opskrift: Blend ingredienser med en gaffel eller blender. Form bøfferne i dine hænder og steg dem (5-10 minutter per side).
A35: Dip | C35: =CookingComponents!C52&" "&CookingComponents!C25 -> Shortcut recipe: Cook then mash with a blender or fork. Taste and balance with salt, sugar, sour, and umami. | D35: =LEN(C35) -> 108 | E35: =CookingComponents!E52&" "&CookingComponents!E25 -> Shortcut opskrift: Kog og blend derefter med en gaffel eller blender. Smag til med salt, sukker, syre og umami.
A36: Guacamole | C36: =CookingComponents!C53&" "&CookingComponents!C17 -> Shortcut recipe: Cut and mix ingredients. Mash with fork. Add oil, sours, salt, and sugar. | D36: =LEN(C36) -> 90 | E36: =CookingComponents!E53&" "&CookingComponents!E17 -> Shortcut opskrift: Skær og bland ingredienser. Blend med en gaffel eller blender. Smag til med olie, syre, salt og sukker.
A38: Rosti | C38: =CookingComponents!C55 -> Shortcut recipe: Grate ingredients and mix them with salt, flour, and eggs. Shape patties in your hands and fry them on a pan with oil (5 minutes on each side). | D38: =LEN(C38) -> 160 | E38: =CookingComponents!E55 -> Shortcut opskrift: Riv ingredienser og bland med salt, mel og æg. Form bøfferne i dine hænder og steg dem (5 minutter per side).
A39: Bread | C39: =CookingComponents!C56 -> Shortcut recipe: knead in the wet ingredients into the dry until no flour pockets remain. Raise for 5 hours and bake for 1 hour (180 degrees). | D39: =LEN(C39) -> 142 | E39: =CookingComponents!E56 -> Shortcut opskrift: Ælt de våde ingredienser indi ide tørre, indtil der ikke er mel-lommer. Hæv i mindst 5 timer, bag i ovnen i en time (180 grader).
A40: Marinade | C40: =CookingComponents!C57 -> Shortcut recipe: Mix ingredients and stir around with a fork. | D40: =LEN(C40) -> 61 | E40: =CookingComponents!E57 -> Shortcut opskrift: Bland ingredienser og rør rundt med en gaffel.
A41: Ratatouille | C41: =CookingComponents!C58 -> Shortcut recipe: You can both fry the veggies with onions and spices in the oven (25 minutes, 180 degrees) or the frying pan (15 minutes) | D41: =LEN(C41) -> 137 | E41: =CookingComponents!E58 -> Shortcut opskrift: Du kan både stege ingredienserne (15 minutter) eller bage dem i ovnen (25 minutter).
...

Sheet CookingComponents
A1: Modules | C1: Shorter version | E1: Da
A2: Sofrito | B2: Fry your onions and spices with a bit of oil. Add your condiments. | C2: Shortcut recipe: Fry onions and spices on a pan. | E2: Shortcut opskrift: Steg løg og krydderier på panden.
A3: Trick | B3: Add and evaporate a splash of alcohol among the spices to accentuate the aromas. | C3: Add a splash of alcohol to accentuate aromas | E3: Tilføj en smule alkohol for at vække aromaerne.
A5: Add | C5: Add your veggies and condiments. | E5: Tilføj dine grøntsager og saucer.
A6: Rice | B6: Boil your rice and let them cool. | C6: Shortcut recipe: Boil rice then let them cool. | E6: Shortcut opskrift: Kog ris og lad dem køle.
A7: Risotto | B7: Add risotto rice to the pan and then slowly add water or stock while stirring. | C7: Add rice with a little wine, then add stock and boiling water gradually. | E7: Tilføj ris med en smule vin. Tilføj kogende vand med buillon gradvist.
A8: Fry | B8: Add veggies to the pan. | C8: Add veggies. | E8: Tilføj grøntsager
A9: Roast | B9: Mix your veggies with onions, spices, salt, and oil. Roast at 180 degrees until desired color and texture. | C9: Shortcut recipe: Roast veggies with onion, spices, salt, and oil in the oven. | E9: Shortcut opskrift: Læg grøntsagerne i ovnen med løg, krydderier, salt og olie.
A10: Raw | B10: Wash, cut and mix your base ingredients. | C10: Shortcut recipe: Cut and mix all ingredients. | E10: Shortcut opskrift: Skær og bland alle ingredienser.
A11: Daal | B11: Add lentils to the pan, and then slowly add water or stock while stirring. | C11: Add lentils, then water with stock. | E11: Tilføj linser, dernæst vand med buillon.
A12: Panzanella | B12: Cut your bread in small cubes, mix with oil, salt and pepper and bake in the oven for 10-15 minutes. | C12: Shortcut recipe: 50% is bread. Cut bread in cubes, drizzle with oil and salt, and then bake in oven. Cook and add your other ingredients | E12: Shortcut opskrift: 50% er brød. Skær brøddet i kvadrater, tilføj olie og salt og bag i ovnen. Tilføj til de andre ingredienser.
A13: Omelette1 | B13: Crack the eggs into a bowl and whisk well with salt and pepper, before adding to the pan. | C13: Whisk eggs well with salt, then add to pan. | E13: Bland æg grundigt med salt og andre smags-ingredienser. Tilføj så til panden.
A14: Omelette2 | B14: Run a spatula through the middle of the omelette and tilt the pan to fill up with the runny egg. Omelette is done when there's no more runny egg. | C14: Omelette is done when egg isn't runny. | E14: Omeletten er klar, når ægget ikke løber længere.
A16: Other heating | B16: Cook your other ingredients on the side.
A17: Dressing | B17: Mix in your dressing: Oil, sour ingredients, salt, and sugar. | C17: Add oil, sours, salt, and sugar. | E17: Smag til med olie, syre, salt og sukker.
A18: Stock | B18: Add water with stock/broth. | C18: Add water with stock/broth. | E18: Til føj vand med buillon.
A19: Soup blending | B19: Add a splash of oil, then blend into your desired consistency. | C19: Blend the soup. | E19: Blend suppen.
A21: Mix | B21: Once all your ingredients are cooked and ready to eat, mix them.
A22: Mix if grains | B22: Mix all your ingredients with your boiled grains/noodles. | C22: Mix with cooked grains/noodles. | E22: Bland med kogte nudler/bælgfrugter/korn.
A23: Mix if pasta | B23: Add 1/2 cup of the pasta water to the frying pan for a creamier consistency. Mix all your ingredients with your boiled pasta. | C23: Mix with cooked pasta, including a cup of the pasta water (for creamy consistency). | E23: Ibland den kogte pasta med en kop pasta vand.
A25: Taste | B25: Before toppings, taste and balance your dish by adding salt, sugar, sour, or umami ingredients for increased flavor. | C25: Taste and balance with salt, sugar, sour, and umami. | E25: Smag til med salt, sukker, syre og umami.
A26: Balance | B26: Too sour? Add salt and sugar. Too spicy? Add oil and sugar. Too Salty? Add bitter ingredients or fresh herbs.
A28: Finish | B28: Add toppings and enjoy!
A30: Dish specific texts
A31: Tacos2 | B31: Add your ingredients and toppings to your taco. Enjoy! | C31: Add all to the tacos. Enjoy! | E31: Tilføj alt i dine tacos.
A32: Summer rolls | B32: Place the rice paper in warm water until softened; then lift out and add your ingredients and toppings before closing. Enjoy! | C32: Soften rice paper in warm water, then fill with your ingredients. Enjoy! | E32: Blødgør rispapiret i varmt vand, fyld så med dine ingredienser.
A33: Borscht | C33: Add the beets | E33: Tilføj rødbederne.
A34: Fried rice 1 | C34: Add an umami sauce, sugar, and cold rice that was cooked the day before, and fry for a few more minutes. | E34: Tilføj en umami sauce, sukker, og kold ris fra dagen før. Steg i et par minutter
A35: Pizza | C35: Shortcut recipe: Make your suco of fried onions, spices, and your choice of paste. Add to pizza with your choice of veggies. | E35: Shortcut opskrift: Smør din pizza sauce i tyndt lag (lavet af løg, krydderier og din sauce stegt på en pande). Tilføj dine grøntsager på toppen.
A36: Pilaf | C36: Add rice and toast them briefly. Then add water (with stock) to boil as usual. | E36: Tilføj ris og rist dem kort. Tilføj vand med buillon og kog risene.
A37: Loaded potato | C37: Shortcut recipe: Bake whole potato for up to an hour in oven, scoop out half the inside, and add your filling | E37: Shortcut opskrift: Bag den hele kartoffel i op til en time i ovnen. Grav halvdelen af indmaden ud og tilføj din filling.
A38: Polenta | C38: Shortcut recipe: Whisk polenta into boiling water (with stock) bit-by-bit. | E38: Shortcut opskrift: Bag den hele kartoffel i op til en time i ovnen. Grav halvdelen af indmaden ud og tilføj din filling.
A39: Congee | C39: Add rice and boiling water with stock, let simmer. | E39: Tilføj ris og kogt vand med buillon og lad simre.
A40: Broccoli/cauliflower rice | C40: Shortcut recipe: Grate or use your food processor to make it into 'rice'. Add your spices and condiments. | E40: Shortcut opskrift: Riv eller brug food processeren til at lave 'ris' af din grøntsag. Tilføj dine andre ingredienser.
A41: Gazpacho | C41: Shortcut recipe: Add veggies with bread to a blender and pulse to the desired texture. Cool it down in fridge. | E41: Shortcut opskrift: Tilføj grøntsager med brød i blenderen og glend til din ønskede tekstur. Lad hvile i køleren i mindst en halv time.
A42: Wraps 1 | C42: Pluck the leaves off your cabbage/lettuce, to be used as 'tacos'. | E42: Pluk bladene forsigtigt af dine kål/salat for at bruge dem som 'tacos'.
A43: Wraps 2 | C43: Add all to the 'tacos'. Enjoy! | E43: Tilføj i din 'tacos'.
A44: Burito | C44: Add all in the burritos. Enjoy | E44: Tilføj alt i dine burritos.
... A79: Overnight oats | C79: Shortcut recipe: Leave oats in liquids over night in the fridge (at least 3 hours). You can still gently heat it next day if you prefer it warm. | E79: Shortcut opskrift: Læg havren i blød over natten i køleren. Du kan stadig varme grøden næste morgen, hvis du foretrækker den varm.

Sheet DishDescriptions
A1: dish_name | B1: dish_pk | C1: mltext_pk | D1: Type | E1: New text | F1: en | G1: da | H1: de | I1: lv | J1: et | K1: lt | L1: es
A2: Pickling | B2: 141 | C2: 1740 | D2: =VLOOKUP(B2,[1]ManipulationPage!$A$3:$D$541,4,FALSE) -> 0 | E2: =IF(VLOOKUP(B2,DishNotes!$B$2:$E$573,4,FALSE)="!","!","") | F2: Add a pleasant sour flavor to any dish you make by pickling your favorite vegetables. | G2: Add a pleasant sour flavor to any dish you make by pickling your favorite vegetables. | H2: Add a pleasant sour flavor to any dish you make by pickling your favorite vegetables.
A3: Asian Marinade | B3: 1094 | C3: 9262 | D3: =VLOOKUP(B3,[1]ManipulationPage!$A$3:$D$541,4,FALSE) -> Asia | E3: =IF(VLOOKUP(B3,DishNotes!$B$2:$E$573,4,FALSE)="!","!","") | F3: Create a delicious marinade to give an Asian twist to your vegetables or tofu. | G3: Lav en lækker marinade for at give et asiatisk twist til dine grøntsager eller tofu. | H3: Stelle eine köstliche Marinade her, um deinem Gemüse oder Tofu eine asiatische Note zu verleihen.
A4: Asian Marinade | B4: 101 | C4: 1478 | D4: =VLOOKUP(B4,[1]ManipulationPage!$A$3:$D$541,4,FALSE) -> Asia | E4: =IF(VLOOKUP(B4,DishNotes!$B$2:$E$573,4,FALSE)="!","!","") | F4: Create a delicious marinade to give an Asian twist to your vegetables or tofu. | G4: Lav en lækker marinade for at give et asiatisk twist til dine grøntsager eller tofu. | H4: Stelle eine köstliche Marinade her, um deinem Gemüse oder Tofu eine asiatische Note zu verleihen.
